Workbook
Name CadastroEquipes: Equipes!$A$2:$A$1000

Sheet Atualização
A1: ATUALIZAÇÃO SEMANAL — FILA DE LIGAS
A2: Controle histórico: manter até 15 partidas por equipe em Dados · cálculos usam as 12 mais recentes · atualizações organizadas em blocos por liga
A4: FLUXO OPERACIONAL
A5: 1. Priorizar ligas com status REVISAR · 2. Buscar resultados concluídos nas fontes indicadas · 3. Padronizar nomes e horários · 4. Inserir somente chaves novas · 5. Durante cada atualização, manter os registros da liga juntos e inserir os jogos do mais antigo para o mais recente · 6. Manter até 15 jogos por equipe em Dados · 7. Recalcular as marcações da janela ativa de 12 · 8. Auditar duplicidades, placares e fórmulas.
A8: STATUS DA BASE
A9: =COUNTIF(H15:H111,"OK — 12+")&" ligas completas" -> 31 ligas completas | E9: =COUNTIF(H15:H111,"REVISAR")&" ligas para revisar" -> 8 ligas para revisar | I9: Último jogo na base
I10: =MAX(G15:G111) -> 46247
A13: FILA DETALHADA
A14: País | B14: Liga | C14: Perfil | D14: Partidas | E14: Equipes | F14: Mín. jogos/equipe | G14: Último jogo | H14: Status | I14: Fonte sugerida | J14: Ação
A15: ARG | B15: Liga Profesional | C15: Poucos Gols | D15: =COUNTIFS(tblDados[País],A15,tblDados[Liga],B15,tblDados[Janela_12_Liga],1) -> 4 | E15: {=IFERROR(ROWS(_xlfn.UNIQUE(_xlfn.VSTACK(_xlfn._xlws.FILTER(tblDados[Mandante],(tblDados[País]=A15)*(tblDados[Liga]=B15)*(tblDados[Janela_12_Liga]=1)),_xlfn._xlws.FILTER(tblDados[Visitante],(tblDados[País]=A15)*(tblDados[Liga]=B15)*(tblDados[Janela_12_Liga]=1))))),0)} -> 8 | F15: {=_xlfn.LET(_xlpm.p,A15,_xlpm.l,B15,_xlpm.t,_xlfn.UNIQUE(_xlfn.VSTACK(_xlfn._xlws.FILTER(tblDados[Mandante],(tblDados[País]=_xlpm.p)*(tblDados[Liga]=_xlpm.l)*(tblDados[Janela_12_Liga]=1)),_xlfn._xlws.FILTER(tblDados[Visitante],(tblDados[País]=_xlpm.p)*(tblDados[Liga]=_xlpm.l)*(tblDados[Janela_12_Liga]=1)))),IFERROR(MIN(_xlfn.MAP(_xlpm.t,_xlfn.LAMBDA(_xlpm.x,SUMPRODUCT((tblDados[Mandante]=_xlpm.x)*(tblDados[País]=_xlpm.p)*(tblDados[Liga]=_xlpm.l)*tblDados[Janela_12_Mandante])+SUMPRODUCT((tblDados[Visitante]=_xlpm.x)*(tblDados[País]=_xlpm.p)*(tblDados[Liga]=_xlpm.l)*tblDados[Janela_12_Visitante])))),0))} -> 1 | G15: =IFERROR(_xlfn.MAXIFS(tblDados[Data],tblDados[País],A15,tblDados[Liga],B15,tblDados[Janela_12_Liga],1),"") -> 46230 | H15: =IF(F15>=12,"OK — 12+","REVISAR") -> REVISAR | I15: WorldFootball · Futbol24 · Flashscore | J15: =IF(H15="OK — 12+","Manutenção semanal","Completar janela") -> Completar janela
A16: ARG | B16: Primera Nacional | C16: Poucos Gols | D16: =COUNTIFS(tblDados[País],A16,tblDados[Liga],B16,tblDados[Janela_12_Liga],1) -> 2 | E16: {=IFERROR(ROWS(_xlfn.UNIQUE(_xlfn.VSTACK(_xlfn._xlws.FILTER(tblDados[Mandante],(tblDados[País]=A16)*(tblDados[Liga]=B16)*(tblDados[Janela_12_Liga]=1)),_xlfn._xlws.FILTER(tblDados[Visitante],(tblDados[País]=A16)*(tblDados[Liga]=B16)*(tblDados[Janela_12_Liga]=1))))),0)} -> 4 | F16: {=_xlfn.LET(_xlpm.p,A16,_xlpm.l,B16,_xlpm.t,_xlfn.UNIQUE(_xlfn.VSTACK(_xlfn._xlws.FILTER(tblDados[Mandante],(tblDados[País]=_xlpm.p)*(tblDados[Liga]=_xlpm.l)*(tblDados[Janela_12_Liga]=1)),_xlfn._xlws.FILTER(tblDados[Visitante],(tblDados[País]=_xlpm.p)*(tblDados[Liga]=_xlpm.l)*(tblDados[Janela_12_Liga]=1)))),IFERROR(MIN(_xlfn.MAP(_xlpm.t,_xlfn.LAMBDA(_xlpm.x,SUMPRODUCT((tblDados[Mandante]=_xlpm.x)*(tblDados[País]=_xlpm.p)*(tblDados[Liga]=_xlpm.l)*tblDados[Janela_12_Mandante])+SUMPRODUCT((tblDados[Visitante]=_xlpm.x)*(tblDados[País]=_xlpm.p)*(tblDados[Liga]=_xlpm.l)*tblDados[Janela_12_Visitante])))),0))} -> 1 | G16: =IFERROR(_xlfn.MAXIFS(tblDados[Data],tblDados[País],A16,tblDados[Liga],B16,tblDados[Janela_12_Liga],1),"") -> 46230 | H16: =IF(F16>=12,"OK — 12+","REVISAR") -> REVISAR | I16: WorldFootball · Futbol24 · Flashscore | J16: =IF(H16="OK — 12+","Manutenção semanal","Completar janela") -> Completar janela
A17: BOL | B17: Div. Profesional | C17: Muitos Gols | D17: =COUNTIFS(tblDados[País],A17,tblDados[Liga],B17,tblDados[Janela_12_Liga],1) -> 97 | E17: {=IFERROR(ROWS(_xlfn.UNIQUE(_xlfn.VSTACK(_xlfn._xlws.FILTER(tblDados[Mandante],(tblDados[País]=A17)*(tblDados[Liga]=B17)*(tblDados[Janela_12_Liga]=1)),_xlfn._xlws.FILTER(tblDados[Visitante],(tblDados[País]=A17)*(tblDados[Liga]=B17)*(tblDados[Janela_12_Liga]=1))))),0)} -> 16 | F17: {=_xlfn.LET(_xlpm.p,A17,_xlpm.l,B17,_xlpm.t,_xlfn.UNIQUE(_xlfn.VSTACK(_xlfn._xlws.FILTER(tblDados[Mandante],(tblDados[País]=_xlpm.p)*(tblDados[Liga]=_xlpm.l)*(tblDados[Janela_12_Liga]=1)),_xlfn._xlws.FILTER(tblDados[Visitante],(tblDados[País]=_xlpm.p)*(tblDados[Liga]=_xlpm.l)*(tblDados[Janela_12_Liga]=1)))),IFERROR(MIN(_xlfn.MAP(_xlpm.t,_xlfn.LAMBDA(_xlpm.x,SUMPRODUCT((tblDados[Mandante]=_xlpm.x)*(tblDados[País]=_xlpm.p)*(tblDados[Liga]=_xlpm.l)*tblDados[Janela_12_Mandante])+SUMPRODUCT((tblDados[Visitante]=_xlpm.x)*(tblDados[País]=_xlpm.p)*(tblDados[Liga]=_xlpm.l)*tblDados[Janela_12_Visitante])))),0))} -> 12 | G17: =IFERROR(_xlfn.MAXIFS(tblDados[Data],tblDados[País],A17,tblDados[Liga],B17,tblDados[Janela_12_Liga],1),"") -> 46243 | H17: =IF(F17>=12,"OK — 12+","REVISAR") -> OK — 12+ | I17: WorldFootball · Futbol24 · Flashscore | J17: =IF(H17="OK — 12+","Manutenção semanal","Completar janela") -> Manutenção semanal
A18: BRA | B18: Série A | C18: Equilibrada | D18: =COUNTIFS(tblDados[País],A18,tblDados[Liga],B18,tblDados[Janela_12_Liga],1) -> 124 | E18: {=IFERROR(ROWS(_xlfn.UNIQUE(_xlfn.VSTACK(_xlfn._xlws.FILTER(tblDados[Mandante],(tblDados[País]=A18)*(tblDados[Liga]=B18)*(tblDados[Janela_12_Liga]=1)),_xlfn._xlws.FILTER(tblDados[Visitante],(tblDados[País]=A18)*(tblDados[Liga]=B18)*(tblDados[Janela_12_Liga]=1))))),0)} -> 20 | F18: {=_xlfn.LET(_xlpm.p,A18,_xlpm.l,B18,_xlpm.t,_xlfn.UNIQUE(_xlfn.VSTACK(_xlfn._xlws.FILTER(tblDados[Mandante],(tblDados[País]=_xlpm.p)*(tblDados[Liga]=_xlpm.l)*(tblDados[Janela_12_Liga]=1)),_xlfn._xlws.FILTER(tblDados[Visitante],(tblDados[País]=_xlpm.p)*(tblDados[Liga]=_xlpm.l)*(tblDados[Janela_12_Liga]=1)))),IFERROR(MIN(_xlfn.MAP(_xlpm.t,_xlfn.LAMBDA(_xlpm.x,SUMPRODUCT((tblDados[Mandante]=_xlpm.x)*(tblDados[País]=_xlpm.p)*(tblDados[Liga]=_xlpm.l)*tblDados[Janela_12_Mandante])+SUMPRODUCT((tblDados[Visitante]=_xlpm.x)*(tblDados[País]=_xlpm.p)*(tblDados[Liga]=_xlpm.l)*tblDados[Janela_12_Visitante])))),0))} -> 12 | G18: =IFERROR(_xlfn.MAXIFS(tblDados[Data],tblDados[País],A18,tblDados[Liga],B18,tblDados[Janela_12_Liga],1),"") -> 46233 | H18: =IF(F18>=12,"OK — 12+","REVISAR") -> OK — 12+ | I18: WorldFootball · Futbol24 · Flashscore | J18: =IF(H18="OK — 12+","Manutenção semanal","Completar janela") -> Manutenção semanal
A19: BRA | B19: Série B | C19: Poucos Gols | D19: =COUNTIFS(tblDados[País],A19,tblDados[Liga],B19,tblDados[Janela_12_Liga],1) -> 120 | E19: {=IFERROR(ROWS(_xlfn.UNIQUE(_xlfn.VSTACK(_xlfn._xlws.FILTER(tblDados[Mandante],(tblDados[País]=A19)*(tblDados[Liga]=B19)*(tblDados[Janela_12_Liga]=1)),_xlfn._xlws.FILTER(tblDados[Visitante],(tblDados[País]=A19)*(tblDados[Liga]=B19)*(tblDados[Janela_12_Liga]=1))))),0)} -> 20 | F19: {=_xlfn.LET(_xlpm.p,A19,_xlpm.l,B19,_xlpm.t,_xlfn.UNIQUE(_xlfn.VSTACK(_xlfn._xlws.FILTER(tblDados[Mandante],(tblDados[País]=_xlpm.p)*(tblDados[Liga]=_xlpm.l)*(tblDados[Janela_12_Liga]=1)),_xlfn._xlws.FILTER(tblDados[Visitante],(tblDados[País]=_xlpm.p)*(tblDados[Liga]=_xlpm.l)*(tblDados[Janela_12_Liga]=1)))),IFERROR(MIN(_xlfn.MAP(_xlpm.t,_xlfn.LAMBDA(_xlpm.x,SUMPRODUCT((tblDados[Mandante]=_xlpm.x)*(tblDados[País]=_xlpm.p)*(tblDados[Liga]=_xlpm.l)*tblDados[Janela_12_Mandante])+SUMPRODUCT((tblDados[Visitante]=_xlpm.x)*(tblDados[País]=_xlpm.p)*(tblDados[Liga]=_xlpm.l)*tblDados[Janela_12_Visitante])))),0))} -> 12 | G19: =IFERROR(_xlfn.MAXIFS(tblDados[Data],tblDados[País],A19,tblDados[Liga],B19,tblDados[Janela_12_Liga],1),"") -> 46245 | H19: =IF(F19>=12,"OK — 12+","REVISAR") -> OK — 12+ | I19: WorldFootball · Futbol24 · Flashscore | J19: =IF(H19="OK — 12+","Manutenção semanal","Completar janela") -> Manutenção semanal
A20: BRA | B20: Série C | C20: Poucos Gols | D20: =COUNTIFS(tblDados[País],A20,tblDados[Liga],B20,tblDados[Janela_12_Liga],1) -> 121 | E20: {=IFERROR(ROWS(_xlfn.UNIQUE(_xlfn.VSTACK(_xlfn._xlws.FILTER(tblDados[Mandante],(tblDados[País]=A20)*(tblDados[Liga]=B20)*(tblDados[Janela_12_Liga]=1)),_xlfn._xlws.FILTER(tblDados[Visitante],(tblDados[País]=A20)*(tblDados[Liga]=B20)*(tblDados[Janela_12_Liga]=1))))),0)} -> 20 | F20: {=_xlfn.LET(_xlpm.p,A20,_xlpm.l,B20,_xlpm.t,_xlfn.UNIQUE(_xlfn.VSTACK(_xlfn._xlws.FILTER(tblDados[Mandante],(tblDados[País]=_xlpm.p)*(tblDados[Liga]=_xlpm.l)*(tblDados[Janela_12_Liga]=1)),_xlfn._xlws.FILTER(tblDados[Visitante],(tblDados[País]=_xlpm.p)*(tblDados[Liga]=_xlpm.l)*(tblDados[Janela_12_Liga]=1)))),IFERROR(MIN(_xlfn.MAP(_xlpm.t,_xlfn.LAMBDA(_xlpm.x,SUMPRODUCT((tblDados[Mandante]=_xlpm.x)*(tblDados[País]=_xlpm.p)*(tblDados[Liga]=_xlpm.l)*tblDados[Janela_12_Mandante])+SUMPRODUCT((tblDados[Visitante]=_xlpm.x)*(tblDados[País]=_xlpm.p)*(tblDados[Liga]=_xlpm.l)*tblDados[Janela_12_Visitante])))),0))} -> 12 | G20: =IFERROR(_xlfn.MAXIFS(tblDados[Data],tblDados[País],A20,tblDados[Liga],B20,tblDados[Janela_12_Liga],1),"") -> 46244 | H20: =IF(F20>=12,"OK — 12+","REVISAR") -> OK — 12+ | I20: WorldFootball · Futbol24 · Flashscore | J20: =IF(H20="OK — 12+","Manutenção semanal","Completar janela") -> Manutenção semanal
A21: CAN | B21: Premier League | C21: Equilibrada | D21: =COUNTIFS(tblDados[País],A21,tblDados[Liga],B21,tblDados[Janela_12_Liga],1) -> 49 | E21: {=IFERROR(ROWS(_xlfn.UNIQUE(_xlfn.VSTACK(_xlfn._xlws.FILTER(tblDados[Mandante],(tblDados[País]=A21)*(tblDados[Liga]=B21)*(tblDados[Janela_12_Liga]=1)),_xlfn._xlws.FILTER(tblDados[Visitante],(tblDados[País]=A21)*(tblDados[Liga]=B21)*(tblDados[Janela_12_Liga]=1))))),0)} -> 8 | F21: {=_xlfn.LET(_xlpm.p,A21,_xlpm.l,B21,_xlpm.t,_xlfn.UNIQUE(_xlfn.VSTACK(_xlfn._xlws.FILTER(tblDados[Mandante],(tblDados[País]=_xlpm.p)*(tblDados[Liga]=_xlpm.l)*(tblDados[Janela_12_Liga]=1)),_xlfn._xlws.FILTER(tblDados[Visitante],(tblDados[País]=_xlpm.p)*(tblDados[Liga]=_xlpm.l)*(tblDados[Janela_12_Liga]=1)))),IFERROR(MIN(_xlfn.MAP(_xlpm.t,_xlfn.LAMBDA(_xlpm.x,SUMPRODUCT((tblDados[Mandante]=_xlpm.x)*(tblDados[País]=_xlpm.p)*(tblDados[Liga]=_xlpm.l)*tblDados[Janela_12_Mandante])+SUMPRODUCT((tblDados[Visitante]=_xlpm.x)*(tblDados[País]=_xlpm.p)*(tblDados[Liga]=_xlpm.l)*tblDados[Janela_12_Visitante])))),0))} -> 12 | G21: =IFERROR(_xlfn.MAXIFS(tblDados[Data],tblDados[País],A21,tblDados[Liga],B21,tblDados[Janela_12_Liga],1),"") -> 46242 | H21: =IF(F21>=12,"OK — 12+","REVISAR") -> OK — 12+ | I21: WorldFootball · Futbol24 · Flashscore | J21: =IF(H21="OK — 12+","Manutenção semanal","Completar janela") -> Manutenção semanal
A22: CHI | B22: Liga de Primera | C22: Equilibrada | D22: =COUNTIFS(tblDados[País],A22,tblDados[Liga],B22,tblDados[Janela_12_Liga],1) -> 98 | E22: {=IFERROR(ROWS(_xlfn.UNIQUE(_xlfn.VSTACK(_xlfn._xlws.FILTER(tblDados[Mandante],(tblDados[País]=A22)*(tblDados[Liga]=B22)*(tblDados[Janela_12_Liga]=1)),_xlfn._xlws.FILTER(tblDados[Visitante],(tblDados[País]=A22)*(tblDados[Liga]=B22)*(tblDados[Janela_12_Liga]=1))))),0)} -> 16 | F22: {=_xlfn.LET(_xlpm.p,A22,_xlpm.l,B22,_xlpm.t,_xlfn.UNIQUE(_xlfn.VSTACK(_xlfn._xlws.FILTER(tblDados[Mandante],(tblDados[País]=_xlpm.p)*(tblDados[Liga]=_xlpm.l)*(tblDados[Janela_12_Liga]=1)),_xlfn._xlws.FILTER(tblDados[Visitante],(tblDados[País]=_xlpm.p)*(tblDados[Liga]=_xlpm.l)*(tblDados[Janela_12_Liga]=1)))),IFERROR(MIN(_xlfn.MAP(_xlpm.t,_xlfn.LAMBDA(_xlpm.x,SUMPRODUCT((tblDados[Mandante]=_xlpm.x)*(tblDados[País]=_xlpm.p)*(tblDados[Liga]=_xlpm.l)*tblDados[Janela_12_Mandante])+SUMPRODUCT((tblDados[Visitante]=_xlpm.x)*(tblDados[País]=_xlpm.p)*(tblDados[Liga]=_xlpm.l)*tblDados[Janela_12_Visitante])))),0))} -> 12 | G22: =IFERROR(_xlfn.MAXIFS(tblDados[Data],tblDados[País],A22,tblDados[Liga],B22,tblDados[Janela_12_Liga],1),"") -> 46244 | H22: =IF(F22>=12,"OK — 12+","REVISAR") -> OK — 12+ | I22: WorldFootball · Futbol24 · Flashscore | J22: =IF(H22="OK — 12+","Manutenção semanal","Completar janela") -> Manutenção semanal
A23: ECU | B23: LigaPro Serie A | C23: Equilibrada | D23: =COUNTIFS(tblDados[País],A23,tblDados[Liga],B23,tblDados[Janela_12_Liga],1) -> 96 | E23: {=IFERROR(ROWS(_xlfn.UNIQUE(_xlfn.VSTACK(_xlfn._xlws.FILTER(tblDados[Mandante],(tblDados[País]=A23)*(tblDados[Liga]=B23)*(tblDados[Janela_12_Liga]=1)),_xlfn._xlws.FILTER(tblDados[Visitante],(tblDados[País]=A23)*(tblDados[Liga]=B23)*(tblDados[Janela_12_Liga]=1))))),0)} -> 16 | F23: {=_xlfn.LET(_xlpm.p,A23,_xlpm.l,B23,_xlpm.t,_xlfn.UNIQUE(_xlfn.VSTACK(_xlfn._xlws.FILTER(tblDados[Mandante],(tblDados[País]=_xlpm.p)*(tblDados[Liga]=_xlpm.l)*(tblDados[Janela_12_Liga]=1)),_xlfn._xlws.FILTER(tblDados[Visitante],(tblDados[País]=_xlpm.p)*(tblDados[Liga]=_xlpm.l)*(tblDados[Janela_12_Liga]=1)))),IFERROR(MIN(_xlfn.MAP(_xlpm.t,_xlfn.LAMBDA(_xlpm.x,SUMPRODUCT((tblDados[Mandante]=_xlpm.x)*(tblDados[País]=_xlpm.p)*(tblDados[Liga]=_xlpm.l)*tblDados[Janela_12_Mandante])+SUMPRODUCT((tblDados[Visitante]=_xlpm.x)*(tblDados[País]=_xlpm.p)*(tblDados[Liga]=_xlpm.l)*tblDados[Janela_12_Visitante])))),0))} -> 12 | G23: =IFERROR(_xlfn.MAXIFS(tblDados[Data],tblDados[País],A23,tblDados[Liga],B23,tblDados[Janela_12_Liga],1),"") -> 46244 | H23: =IF(F23>=12,"OK — 12+","REVISAR") -> OK — 12+ | I23: WorldFootball · Futbol24 · Flashscore | J23: =IF(H23="OK — 12+","Manutenção semanal","Completar janela") -> Manutenção semanal
A24: FIN | B24: Veikkausliiga | C24: Equilibrada | D24: =COUNTIFS(tblDados[País],A24,tblDados[Liga],B24,tblDados[Janela_12_Liga],1) -> 75 | E24: {=IFERROR(ROWS(_xlfn.UNIQUE(_xlfn.VSTACK(_xlfn._xlws.FILTER(tblDados[Mandante],(tblDados[País]=A24)*(tblDados[Liga]=B24)*(tblDados[Janela_12_Liga]=1)),_xlfn._xlws.FILTER(tblDados[Visitante],(tblDados[País]=A24)*(tblDados[Liga]=B24)*(tblDados[Janela_12_Liga]=1))))),0)} -> 12 | F24: {=_xlfn.LET(_xlpm.p,A24,_xlpm.l,B24,_xlpm.t,_xlfn.UNIQUE(_xlfn.VSTACK(_xlfn._xlws.FILTER(tblDados[Mandante],(tblDados[País]=_xlpm.p)*(tblDados[Liga]=_xlpm.l)*(tblDados[Janela_12_Liga]=1)),_xlfn._xlws.FILTER(tblDados[Visitante],(tblDados[País]=_xlpm.p)*(tblDados[Liga]=_xlpm.l)*(tblDados[Janela_12_Liga]=1)))),IFERROR(MIN(_xlfn.MAP(_xlpm.t,_xlfn.LAMBDA(_xlpm.x,SUMPRODUCT((tblDados[Mandante]=_xlpm.x)*(tblDados[País]=_xlpm.p)*(tblDados[Liga]=_xlpm.l)*tblDados[Janela_12_Mandante])+SUMPRODUCT((tblDados[Visitante]=_xlpm.x)*(tblDados[País]=_xlpm.p)*(tblDados[Liga]=_xlpm.l)*tblDados[Janela_12_Visitante])))),0))} -> 12 | G24: =IFERROR(_xlfn.MAXIFS(tblDados[Data],tblDados[País],A24,tblDados[Liga],B24,tblDados[Janela_12_Liga],1),"") -> 46243 | H24: =IF(F24>=12,"OK — 12+","REVISAR") -> OK — 12+ | I24: WorldFootball · Futbol24 · Flashscore | J24: =IF(H24="OK — 12+","Manutenção semanal","Completar janela") -> Manutenção semanal
A25: FIN | B25: Ykkösliiga | C25: Equilibrada | D25: =COUNTIFS(tblDados[País],A25,tblDados[Liga],B25,tblDados[Janela_12_Liga],1) -> 62 | E25: {=IFERROR(ROWS(_xlfn.UNIQUE(_xlfn.VSTACK(_xlfn._xlws.FILTER(tblDados[Mandante],(tblDados[País]=A25)*(tblDados[Liga]=B25)*(tblDados[Janela_12_Liga]=1)),_xlfn._xlws.FILTER(tblDados[Visitante],(tblDados[País]=A25)*(tblDados[Liga]=B25)*(tblDados[Janela_12_Liga]=1))))),0)} -> 10 | F25: {=_xlfn.LET(_xlpm.p,A25,_xlpm.l,B25,_xlpm.t,_xlfn.UNIQUE(_xlfn.VSTACK(_xlfn._xlws.FILTER(tblDados[Mandante],(tblDados[País]=_xlpm.p)*(tblDados[Liga]=_xlpm.l)*(tblDados[Janela_12_Liga]=1)),_xlfn._xlws.FILTER(tblDados[Visitante],(tblDados[País]=_xlpm.p)*(tblDados[Liga]=_xlpm.l)*(tblDados[Janela_12_Liga]=1)))),IFERROR(MIN(_xlfn.MAP(_xlpm.t,_xlfn.LAMBDA(_xlpm.x,SUMPRODUCT((tblDados[Mandante]=_xlpm.x)*(tblDados[País]=_xlpm.p)*(tblDados[Liga]=_xlpm.l)*tblDados[Janela_12_Mandante])+SUMPRODUCT((tblDados[Visitante]=_xlpm.x)*(tblDados[País]=_xlpm.p)*(tblDados[Liga]=_xlpm.l)*tblDados[Janela_12_Visitante])))),0))} -> 12 | G25: =IFERROR(_xlfn.MAXIFS(tblDados[Data],tblDados[País],A25,tblDados[Liga],B25,tblDados[Janela_12_Liga],1),"") -> 46243 | H25: =IF(F25>=12,"OK — 12+","REVISAR") -> OK — 12+ | I25: WorldFootball · Futbol24 · Flashscore | J25: =IF(H25="OK — 12+","Manutenção semanal","Completar janela") -> Manutenção semanal
A26: FIN | B26: Ykkönen | C26: Muitos Gols | D26: =COUNTIFS(tblDados[País],A26,tblDados[Liga],B26,tblDados[Janela_12_Liga],1) -> 73 | E26: {=IFERROR(ROWS(_xlfn.UNIQUE(_xlfn.VSTACK(_xlfn._xlws.FILTER(tblDados[Mandante],(tblDados[País]=A26)*(tblDados[Liga]=B26)*(tblDados[Janela_12_Liga]=1)),_xlfn._xlws.FILTER(tblDados[Visitante],(tblDados[País]=A26)*(tblDados[Liga]=B26)*(tblDados[Janela_12_Liga]=1))))),0)} -> 12 | F26: {=_xlfn.LET(_xlpm.p,A26,_xlpm.l,B26,_xlpm.t,_xlfn.UNIQUE(_xlfn.VSTACK(_xlfn._xlws.FILTER(tblDados[Mandante],(tblDados[País]=_xlpm.p)*(tblDados[Liga]=_xlpm.l)*(tblDados[Janela_12_Liga]=1)),_xlfn._xlws.FILTER(tblDados[Visitante],(tblDados[País]=_xlpm.p)*(tblDados[Liga]=_xlpm.l)*(tblDados[Janela_12_Liga]=1)))),IFERROR(MIN(_xlfn.MAP(_xlpm.t,_xlfn.LAMBDA(_xlpm.x,SUMPRODUCT((tblDados[Mandante]=_xlpm.x)*(tblDados[País]=_xlpm.p)*(tblDados[Liga]=_xlpm.l)*tblDados[Janela_12_Mandante])+SUMPRODUCT((tblDados[Visitante]=_xlpm.x)*(tblDados[País]=_xlpm.p)*(tblDados[Liga]=_xlpm.l)*tblDados[Janela_12_Visitante])))),0))} -> 12 | G26: =IFERROR(_xlfn.MAXIFS(tblDados[Data],tblDados[País],A26,tblDados[Liga],B26,tblDados[Janela_12_Liga],1),"") -> 46245 | H26: =IF(F26>=12,"OK — 12+","REVISAR") -> OK — 12+ | I26: WorldFootball · Futbol24 · Flashscore | J26: =IF(H26="OK — 12+","Manutenção semanal","Completar janela") -> Manutenção semanal
... A52: AUS | B52: NPL Western Australia | C52: Muitos Gols | D52: =COUNTIFS(tblDados[País],A52,tblDados[Liga],B52,tblDados[Janela_12_Liga],1) -> 72 | E52: {=IFERROR(ROWS(_xlfn.UNIQUE(_xlfn.VSTACK(_xlfn._xlws.FILTER(tblDados[Mandante],(tblDados[País]=A52)*(tblDados[Liga]=B52)*(tblDados[Janela_12_Liga]=1)),_xlfn._xlws.FILTER(tblDados[Visitante],(tblDados[País]=A52)*(tblDados[Liga]=B52)*(tblDados[Janela_12_Liga]=1))))),0)} -> 12 | F52: {=_xlfn.LET(_xlpm.p,A52,_xlpm.l,B52,_xlpm.t,_xlfn.UNIQUE(_xlfn.VSTACK(_xlfn._xlws.FILTER(tblDados[Mandante],(tblDados[País]=_xlpm.p)*(tblDados[Liga]=_xlpm.l)*(tblDados[Janela_12_Liga]=1)),_xlfn._xlws.FILTER(tblDados[Visitante],(tblDados[País]=_xlpm.p)*(tblDados[Liga]=_xlpm.l)*(tblDados[Janela_12_Liga]=1)))),IFERROR(MIN(_xlfn.MAP(_xlpm.t,_xlfn.LAMBDA(_xlpm.x,SUMPRODUCT((tblDados[Mandante]=_xlpm.x)*(tblDados[País]=_xlpm.p)*(tblDados[Liga]=_xlpm.l)*tblDados[Janela_12_Mandante])+SUMPRODUCT((tblDados[Visitante]=_xlpm.x)*(tblDados[País]=_xlpm.p)*(tblDados[Liga]=_xlpm.l)*tblDados[Janela_12_Visitante])))),0))} -> 12 | G52: =IFERROR(_xlfn.MAXIFS(tblDados[Data],tblDados[País],A52,tblDados[Liga],B52,tblDados[Janela_12_Liga],1),"") -> 46241 | H52: =IF(F52>=12,"OK — 12+","REVISAR") -> OK — 12+ | I52: WorldFootball · Futbol24 · Flashscore | J52: =IF(H52="OK — 12+","Manutenção semanal","Completar janela") -> Manutenção semanal
A53: KOR | B53: K League 1 | C53: Poucos Gols | D53: =COUNTIFS(tblDados[País],A53,tblDados[Liga],B53,tblDados[Janela_12_Liga],1) -> 57 | E53: {=IFERROR(ROWS(_xlfn.UNIQUE(_xlfn.VSTACK(_xlfn._xlws.FILTER(tblDados[Mandante],(tblDados[País]=A53)*(tblDados[Liga]=B53)*(tblDados[Janela_12_Liga]=1)),_xlfn._xlws.FILTER(tblDados[Visitante],(tblDados[País]=A53)*(tblDados[Liga]=B53)*(tblDados[Janela_12_Liga]=1))))),0)} -> 12 | F53: {=_xlfn.LET(_xlpm.p,A53,_xlpm.l,B53,_xlpm.t,_xlfn.UNIQUE(_xlfn.VSTACK(_xlfn._xlws.FILTER(tblDados[Mandante],(tblDados[País]=_xlpm.p)*(tblDados[Liga]=_xlpm.l)*(tblDados[Janela_12_Liga]=1)),_xlfn._xlws.FILTER(tblDados[Visitante],(tblDados[País]=_xlpm.p)*(tblDados[Liga]=_xlpm.l)*(tblDados[Janela_12_Liga]=1)))),IFERROR(MIN(_xlfn.MAP(_xlpm.t,_xlfn.LAMBDA(_xlpm.x,SUMPRODUCT((tblDados[Mandante]=_xlpm.x)*(tblDados[País]=_xlpm.p)*(tblDados[Liga]=_xlpm.l)*tblDados[Janela_12_Mandante])+SUMPRODUCT((tblDados[Visitante]=_xlpm.x)*(tblDados[País]=_xlpm.p)*(tblDados[Liga]=_xlpm.l)*tblDados[Janela_12_Visitante])))),0))} -> 6 | G53: =IFERROR(_xlfn.MAXIFS(tblDados[Data],tblDados[País],A53,tblDados[Liga],B53,tblDados[Janela_12_Liga],1),"") -> 46242 | H53: PARCIAL — 6 equipes | I53: WorldFootball · AiScore · Sofascore | J53: Completar liga posteriormente
A54: PRÓXIMAS PARTIDAS — K LEAGUE 1 (GMT−3)
A55: Data | B55: Hora GMT−3 | C55: Mandante | D55: Visitante | E55: Liga | F55: Fuso original | G55: Hora KST | H55: Status | I55: Fonte | J55: Ação
A56: 16/08/2026 | B56: 0.3125 | C56: Ulsan HD FC | D56: Gangwon FC | E56: K League 1 | F56: KST (UTC+9) | G56: 0.8125 | H56: Agendada | I56: Dailysports · WorldFootball | J56: Analisar
A57: 16/08/2026 | B57: 0.3125 | C57: Incheon United | D57: Gimcheon Sangmu | E57: K League 1 | F57: KST (UTC+9) | G57: 0.8125 | H57: Agendada | I57: Dailysports · WorldFootball | J57: Analisar
A58: 16/08/2026 | B58: 0.3125 | C58: Bucheon FC 1995 | D58: Jeonbuk FC | E58: K League 1 | F58: KST (UTC+9) | G58: 0.8125 | H58: Agendada | I58: Dailysports · WorldFootball | J58: Analisar
A59: KOR | B59: K League 2 | C59: Equilibrada | D59: =COUNTIFS(tblDados[País],A59,tblDados[Liga],B59,tblDados[Janela_12_Liga],1) -> 78 | E59: {=IFERROR(ROWS(_xlfn.UNIQUE(_xlfn.VSTACK(_xlfn._xlws.FILTER(tblDados[Mandante],(tblDados[País]=A59)*(tblDados[Liga]=B59)*(tblDados[Janela_12_Liga]=1)),_xlfn._xlws.FILTER(tblDados[Visitante],(tblDados[País]=A59)*(tblDados[Liga]=B59)*(tblDados[Janela_12_Liga]=1))))),0)} -> 17 | F59: {=_xlfn.LET(_xlpm.p,A59,_xlpm.l,B59,_xlpm.t,_xlfn.UNIQUE(_xlfn.VSTACK(_xlfn._xlws.FILTER(tblDados[Mandante],(tblDados[País]=_xlpm.p)*(tblDados[Liga]=_xlpm.l)*(tblDados[Janela_12_Liga]=1)),_xlfn._xlws.FILTER(tblDados[Visitante],(tblDados[País]=_xlpm.p)*(tblDados[Liga]=_xlpm.l)*(tblDados[Janela_12_Liga]=1)))),IFERROR(MIN(_xlfn.MAP(_xlpm.t,_xlfn.LAMBDA(_xlpm.x,SUMPRODUCT((tblDados[Mandante]=_xlpm.x)*(tblDados[País]=_xlpm.p)*(tblDados[Liga]=_xlpm.l)*tblDados[Janela_12_Mandante])+SUMPRODUCT((tblDados[Visitante]=_xlpm.x)*(tblDados[País]=_xlpm.p)*(tblDados[Liga]=_xlpm.l)*tblDados[Janela_12_Visitante])))),0))} -> 6 | G59: =IFERROR(_xlfn.MAXIFS(tblDados[Data],tblDados[País],A59,tblDados[Liga],B59,tblDados[Janela_12_Liga],1),"") -> 46242 | H59: PARCIAL — 8 equipes | I59: WorldFootball · XScores · AiScore · Sofascore | J59: Completar liga posteriormente
A60: PRÓXIMAS PARTIDAS — K LEAGUE 2 (GMT−3)
A61: Data | B61: Hora GMT−3 | C61: Mandante | D61: Visitante | E61: Liga | F61: Fuso original | G61: Hora KST | H61: Status | I61: Fonte | J61: Ação
A62: 16/08/2026 | B62: 0.3125 | C62: Seoul E-Land FC | D62: Ansan Greeners | E62: K League 2 | F62: KST (UTC+9) | G62: 0.8125 | H62: Agendada | I62: Flashscore · Sofascore | J62: Analisar
A63: 16/08/2026 | B63: 0.3125 | C63: Daegu FC | D63: Chungnam Asan FC | E63: K League 2 | F63: KST (UTC+9) | G63: 0.8125 | H63: Agendada | I63: Flashscore · Sofascore | J63: Analisar
A64: 16/08/2026 | B64: 0.3125 | C64: Gimpo FC | D64: Cheonan City FC | E64: K League 2 | F64: KST (UTC+9) | G64: 0.8125 | H64: Agendada | I64: Flashscore · Sofascore | J64: Analisar
A65: 16/08/2026 | B65: 0.3125 | C65: Paju Frontier | D65: Seongnam FC | E65: K League 2 | F65: KST (UTC+9) | G65: 0.8125 | H65: Agendada | I65: Flashscore · Sofascore | J65: Analisar
A66: As fontes usadas são páginas públicas com estruturas diferentes e sujeitas a alterações ou bloqueios. Por isso, um Office Script agendado não consegue reproduzir sozinho a pesquisa e a validação. A alternativa segura é usar esta fila como controle e executar semanalmente uma atualização assistida: pesquisar cada liga, importar resultados concluídos, validar horários e recalcular as janelas.
D69: =COUNTIFS(tblDados[País],A69,tblDados[Liga],B69,tblDados[Janela_12_Liga],1) -> 0 | E69: {=IFERROR(ROWS(_xlfn.UNIQUE(_xlfn.VSTACK(_xlfn._xlws.FILTER(tblDados[Mandante],(tblDados[País]=A69)*(tblDados[Liga]=B69)*(tblDados[Janela_12_Liga]=1)),_xlfn._xlws.FILTER(tblDados[Visitante],(tblDados[País]=A69)*(tblDados[Liga]=B69)*(tblDados[Janela_12_Liga]=1))))),0)} -> 0 | F69: {=_xlfn.LET(_xlpm.p,A69,_xlpm.l,B69,_xlpm.t,_xlfn.UNIQUE(_xlfn.VSTACK(_xlfn._xlws.FILTER(tblDados[Mandante],(tblDados[País]=_xlpm.p)*(tblDados[Liga]=_xlpm.l)*(tblDados[Janela_12_Liga]=1)),_xlfn._xlws.FILTER(tblDados[Visitante],(tblDados[País]=_xlpm.p)*(tblDados[Liga]=_xlpm.l)*(tblDados[Janela_12_Liga]=1)))),IFERROR(MIN(_xlfn.MAP(_xlpm.t,_xlfn.LAMBDA(_xlpm.x,SUMPRODUCT((tblDados[Mandante]=_xlpm.x)*(tblDados[País]=_xlpm.p)*(tblDados[Liga]=_xlpm.l)*tblDados[Janela_12_Mandante])+SUMPRODUCT((tblDados[Visitante]=_xlpm.x)*(tblDados[País]=_xlpm.p)*(tblDados[Liga]=_xlpm.l)*tblDados[Janela_12_Visitante])))),0))} -> 0 | G69: =IFERROR(_xlfn.MAXIFS(tblDados[Data],tblDados[País],A69,tblDados[Liga],B69,tblDados[Janela_12_Liga],1),"") -> 0 | H69: =IF(F69>=12,"OK — 12+","REVISAR") -> REVISAR | I69: WorldFootball · Futbol24 · Flashscore | J69: =IF(H69="OK — 12+","Manutenção semanal","Completar janela") -> Completar janela
A70: COMANDO SEMANAL RECOMENDADO
A71: “Atualize as ligas marcadas como REVISAR e faça manutenção das ligas completas, buscando resultados concluídos desde a última data, mantendo somente a união das últimas 12 partidas por equipe e auditando duplicidades.”

Sheet Memória
A1: MEMÓRIA OPERACIONAL — PROCEDIMENTO DA ABA BACKTEST
A2: Manual permanente para transcrição, liquidação, comparação de linhas e controle visual dos registros. Última atualização: 09/08/2026.
A4: REGRA-MESTRA
A5: Antes de alterar o Backtest, ler esta aba. Cada bilhete finalizado deve ser registrado uma única vez na tblCalibracao. Conferir Bilhetes, odds informadas, observação em Y e linha usada em H. Não inventar odds, linhas ou resultados.
A7: FLUXO OBRIGATÓRIO — PASSO A PASSO
A8: 1 | B8: Identificar o bilhete | C8: Localizar em Bilhetes: data, confronto, liga, placar, linha apostada, odd, stake, resultado e P/L.
A9: 2 | B9: Evitar duplicidade | C9: Normalizar “×” e “x” e confirmar que o confronto ainda não existe na coluna B da tblCalibracao.
A10: 3 | B10: Preencher dados-base | C10: Preencher A:E, G:H e L. A=Data; B=Confronto; C=Liga; D=Placar; E=Odd; G=Gols; H=Usada; L=Fonte odds.
A11: 4 | B11: Calcular P/L usado | C11: F deve ser fórmula viva de liquidação asiática com stake unitária de R$ 0,50. Exceção: cashout usa o lucro líquido real informado.
A12: 5 | B12: Encontrar melhor aproveitamento | C12: Comparar somente as linhas e odds realmente informadas no bilhete. Preencher I=Melhor G, J=Odd M.G. e K=P/L M.G. com a alternativa de maior P/L positivo.
A13: 6 | B13: Sem alternativa positiva | C13: Se nenhuma linha cotada produzir lucro positivo, deixar I:K vazias. Não preencher uma linha hipotética.
A14: 7 | B14: Calcular delta | C14: M = diferença não negativa entre Melhor G e Usada. Se I estiver vazia, M deve ficar vazia.
A15: 8 | B15: Classificar faixas | C15: N:X devem conter fórmulas para O0,50 a O3,00, usando G, ½G, P, ½R ou R.
A16: 9 | B16: Marcar linha usada | C16: Ler H e a observação Y. Marcar somente a célula correspondente em N:X com borda azul-escura espessa e negrito. Remover qualquer outra marcação incorreta na mesma linha.
A17: 10 | B17: Escrever análise | C17: Y deve explicar resultado, linha/odd usada, placar, P/L, melhor alternativa cotada, diferença financeira e aprendizado operacional. Usar o padrão de Y35.
A18: 11 | B18: Cashout | C18: Registrar P/L líquido real; explicar retorno bruto e stake; manter em H a linha original; marcar em N:X o desfecho que teria ocorrido pelo placar final.
A19: 12 | B19: Verificar | C19: Confirmar fórmulas, formatos, ausência de erros, nenhuma duplicidade e todos os campos obrigatórios preenchidos.
A21: MAPA DAS COLUNAS DA tblCalibracao
A22: Coluna | B22: Campo | C22: Tipo | D22: Regra de preenchimento
A23: A | B23: Data | C23: Entrada | D23: Data da partida, formato dd/mm/aa.
A24: B | B24: Confronto | C24: Entrada | D24: Mandante x Visitante; manter nome reconhecível e sem numeração.
A25: C | B25: Liga | C25: Entrada | D25: País - Liga.
A26: D | B26: Placar | C26: Entrada | D26: Mandante x Visitante.
A27: E | B27: Odd | C27: Entrada | D27: Odd da linha usada, preferencialmente 0,000.
A28: F | B28: P/L (R$) | C28: Fórmula / exceção | D28: Liquidação asiática com stake R$ 0,50; cashout recebe lucro líquido real.
A29: G | B29: Gols | C29: Entrada | D29: Soma dos gols do placar.
A30: H | B30: Usada | C30: Entrada | D30: Linha Over realmente apostada. Controla a marcação visual em N:X.
A31: I | B31: Melhor G | C31: Análise | D31: Linha cotada que produziria maior P/L positivo.
A32: J | B32: Odd M.G. | C32: Entrada histórica | D32: Odd informada da Melhor G. Nunca inventar.
A33: K | B33: P/L M.G. | C33: Fórmula | D33: Liquidação da melhor linha com stake R$ 0,50.
... A37: Y | B37: Análise da Entrada | C37: Texto analítico | D37: Narrativa completa seguindo o padrão da linha 35.
A39: LIQUIDAÇÃO DAS LINHAS ASIÁTICAS OVER
A40: Tipo de linha | B40: Exemplo | C40: Liquidação | D40: Regra
A41: Inteira | B41: Over 2,00 | C41: Green / Push / Red | D41: Total > linha = Green; total = linha = Push; total < linha = Red.
A42: Meia | B42: Over 2,50 | C42: Green / Red | D42: Total > linha = Green; caso contrário = Red.
A43: Quarto .25 | B43: Over 2,25 | C43: Green / ½ Red / Red | D43: 3+ = Green; exatamente 2 = ½ Red; 0–1 = Red.
A44: Quarto .75 | B44: Over 2,75 | C44: Green / ½ Green / Red | D44: 4+ = Green; exatamente 3 = ½ Green; 0–2 = Red.
A46: FÓRMULAS-BASE
A47: Campo | B47: Fórmula / lógica
A48: F — P/L usado | B48: FÓRMULA: =IF(OR([@Odd]="",[@Usada]=""),"",LET(t,[@Gols],l,[@Usada],o,[@Odd],n,INT(l),f,ROUND(MOD(l,1),2),IF(f=0,IF(t>l,0.5*(o-1),IF(t=l,0,-0.5)),IF(f=0.5,IF(t>l,0.5*(o-1),-0.5),IF(f=0.25,IF(t>=n+1,0.5*(o-1),IF(t=n,-0.25,-0.5)),IF(f=0.75,IF(t>=n+2,0.5*(o-1),IF(t=n+1,0.25*(o-1),-0.5)),""))))))
...

Sheet Dados
A1: ID_Bilhete | B1: Data | C1: Hora | D1: País | E1: Liga | F1: Partida | G1: Mandante | H1: GM_M | I1: GS_M | J1: Visitante | K1: GM_V | L1: GS_V | M1: Mercado | N1: Linha_Selecao | O1: Odd | P1: Stake | Q1: Resultado_Aposta | R1: Lucro_Prejuizo | S1: Chave_Partida | T1: Primeira_Ocorrencia | U1: Alerta / Sugestão Mandante | V1: Alerta / Sugestão Visitante | W1: Janela_12_Mandante | X1: Janela_12_Visitante | Y1: Janela_12_Liga
A2: 00003-NOR | B2: 46230 | C2: 0.58333333 | D2: NOR | E2: Eliteserien | F2: Rosenborg BK 4 vs 0 Fredrikstad FK | G2: Rosenborg BK | H2: 4 | I2: 0 | J2: Fredrikstad FK | K2: 0 | L2: 4 | M2: Gols +/- | N2: Mais de 2.0 | O2: 1 | P2: 0.5 | Q2: Cashout | R2: 0.13 | S2: 2026-07-27|Rosenborg BK|Fredrikstad FK | T2: 1 | W2: 1 | X2: 1 | Y2: 1
A3: 00005-NOR | B3: 46230 | C3: 0.58333333 | D3: NOR | E3: OBOS-ligaen | F3: Stabæk Fotball 6 vs 0 IL Hødd | G3: Stabæk Fotball | H3: 6 | I3: 0 | J3: IL Hødd | K3: 0 | L3: 6 | M3: Gols +/- | N3: Mais de 3.0 | O3: 1 | P3: 0.5 | Q3: Cashout | R3: 0.19 | S3: 2026-07-27|Stabæk Fotball|IL Hødd | T3: 1 | W3: 1 | X3: 1 | Y3: 1
A4: 00006-SWE | B4: 46230 | C4: 0.58680556 | D4: SWE | E4: Superettan | F4: Östers IF 3 vs 0 Varbergs BoIS FC | G4: Östers IF | H4: 3 | I4: 0 | J4: Varbergs BoIS FC | K4: 0 | L4: 3 | M4: Gols +/- | N4: Mais de 2.0 | O4: 1 | P4: 0.5 | Q4: Cashout | R4: 0.06 | S4: 2026-07-27|Östers IF|Varbergs BoIS FC | T4: 1 | W4: 1 | X4: 1 | Y4: 1
A5: 00008-SWE | B5: 46230 | C5: 0.58333333 | D5: SWE | E5: Allsvenskan | F5: BK Häcken 0 vs 0 AIK | G5: BK Häcken | H5: 0 | I5: 0 | J5: AIK | K5: 0 | L5: 0 | M5: Gols +/- | N5: Mais de 2.0 | O5: 1.17 | P5: 0.5 | Q5: Red | R5: -0.5 | S5: 2026-07-27|BK Häcken|AIK | T5: 1 | W5: 1 | X5: 1 | Y5: 1
A6: 00010-ISL | B6: 46230 | C6: 0.67708333 | D6: ISL | E6: Besta-deild karla (PL) | F6: Breidablik 1 vs 0 IBV Vestmannaeyjar | G6: Breidablik | H6: 1 | I6: 0 | J6: IBV Vestmannaeyjar | K6: 0 | L6: 1 | M6: Gols +/- | N6: Mais de 2.0 | O6: 1.175 | P6: 0.5 | Q6: Red | R6: -0.5 | S6: 2026-07-27|Breidablik|IBV Vestmannaeyjar | T6: 1 | W6: 1 | X6: 1 | Y6: 1
A7: 00012-ISL | B7: 46230 | C7: 0.67708333 | D7: ISL | E7: Besta-deild karla (PL) | F7: KA Akureyri 0 vs 0 Thor Akureyri (Þór Akureyri) | G7: KA Akureyri | H7: 0 | I7: 0 | J7: Thor Akureyri (Þór Akureyri) | K7: 0 | L7: 0 | M7: Gols +/- | N7: Mais de 2.0 | O7: 1.14 | P7: 0.5 | Q7: Red | R7: -0.5 | S7: 2026-07-27|KA Akureyri|Thor Akureyri (Þór Akureyri) | T7: 1 | W7: 1 | X7: 1 | Y7: 1
A8: 00013-BRA | B8: 46230 | C8: 0.83333333 | D8: BRA | E8: Série B | F8: CRB 2 vs 0 Vila Nova | G8: CRB | H8: 2 | I8: 0 | J8: Vila Nova | K8: 0 | L8: 2 | M8: Gols +/- | N8: Mais de 1.0, 1.5 | O8: 1.225 | P8: 0.5 | Q8: Green | R8: 0.12 | S8: 2026-07-27|CRB|Vila Nova | T8: 1 | W8: 1 | X8: 1 | Y8: 1
A9: 00014-BRA | B9: 46230 | C9: 0.83333333 | D9: BRA | E9: Série B | F9: Atlético-GO 3 vs 1 Operário-PR | G9: Atlético-GO | H9: 3 | I9: 1 | J9: Operário-PR | K9: 1 | L9: 3 | M9: Gols +/- | N9: Mais de 1.0 | O9: 1.125 | P9: 0.5 | Q9: Green | R9: 0.07 | S9: 2026-07-27|Atlético-GO|Operário-PR | T9: 1 | W9: 1 | X9: 1 | Y9: 1
A10: 00015-BRA | B10: 46230 | C10: 0.83333333 | D10: BRA | E10: Série B | F10: Sport Recife 1 vs 1 Cuiabá | G10: Sport Recife | H10: 1 | I10: 1 | J10: Cuiabá | K10: 1 | L10: 1 | M10: Gols +/- | N10: Mais de 1.0 | O10: 1.17 | P10: 0.5 | Q10: Red | R10: 0.09 | S10: 2026-07-27|Sport Recife|Cuiabá | T10: 1 | W10: 1 | X10: 1 | Y10: 1
A11: 00017-ISL | B11: 46231 | C11: 0.67708333 | D11: ISL | E11: Lengjudeildin (1ªD) | F11: Aegir 0 vs 1 Njardvik | G11: Aegir | H11: 0 | I11: 1 | J11: Njardvik | K11: 1 | L11: 0 | M11: Gols +/- | N11: Mais de 2.0, 2.5 | O11: 1.17 | P11: 0.5 | Q11: Red | R11: -0.5 | S11: 2026-07-28|Aegir|Njardvik | T11: 1 | W11: 1 | X11: 1 | Y11: 1
A12: 00019-BRA | B12: 46231 | C12: 0.83333333 | D12: BRA | E12: Série B | F12: Ponte Preta 1 vs 1 Athletic Club-MG | G12: Ponte Preta | H12: 1 | I12: 1 | J12: Athletic Club-MG | K12: 1 | L12: 1 | M12: Gols +/- | N12: Mais de 0.5 | O12: 1.105 | P12: 0.5 | Q12: Green | R12: 0.06 | S12: 2026-07-28|Ponte Preta|Athletic Club-MG | T12: 1 | W12: 1 | X12: 1 | Y12: 1
A13: 00020-BRA | B13: 46231 | C13: 0.79166667 | D13: BRA | E13: Série B | F13: Juventude 1 vs 0 Avaí | G13: Juventude | H13: 1 | I13: 0 | J13: Avaí | K13: 0 | L13: 1 | M13: Gols +/- | N13: Mais de 1.0 | O13: 1.12 | P13: 0.5 | Q13: Devolvida | R13: 0 | S13: 2026-07-28|Juventude|Avaí | T13: 1 | W13: 1 | X13: 1 | Y13: 1
... A70: 00099-NOR | B70: 46236 | C70: 0.5 | D70: NOR | E70: OBOS-ligaen | F70: Egersunds IK 2 vs 0 Sandnes Ulf | G70: Egersunds IK | H70: 2 | I70: 0 | J70: Sandnes Ulf | K70: 0 | L70: 2 | M70: Gols +/- | N70: Mais de 2.0 | O70: 1.22 | P70: 0.5 | Q70: Devolvida | R70: 0 | S70: 2026-08-02|Egersunds IK|Sandnes Ulf | T70: 1 | W70: 1 | X70: 1 | Y70: 1
A71: EST-00001 | B71: 46164 | C71: 0.52083333 | D71: FIN | E71: Kakkonen A | F71: Atlantis FC 8 vs 0 PuiU | G71: Atlantis FC | H71: 8 | I71: 0 | J71: PuiU | K71: 0 | L71: 8 | S71: 2026-05-22|Atlantis FC|PuiU | T71: 1 | W71: 1 | X71: 1 | Y71: 1
A72: EST-00002 | B72: 46173 | C72: 0.375 | D72: FIN | E72: Kakkonen A | F72: Reipas (Lahden Reipas) 1 vs 0 Atlantis FC | G72: Reipas (Lahden Reipas) | H72: 1 | I72: 0 | J72: Atlantis FC | K72: 0 | L72: 1 | S72: 2026-05-31|Reipas (Lahden Reipas)|Atlantis FC | T72: 1 | W72: 1 | X72: 1 | Y72: 1
A73: EST-00003 | B73: 46179 | C73: 0.33333333 | D73: FIN | E73: Kakkonen A | F73: Atlantis FC 3 vs 2 HIFK | G73: Atlantis FC | H73: 3 | I73: 2 | J73: HIFK | K73: 2 | L73: 3 | S73: 2026-06-06|Atlantis FC|HIFK | T73: 1 | W73: 1 | X73: 1 | Y73: 1
A74: EST-00004 | B74: 46184 | C74: 0.5 | D74: FIN | E74: Kakkonen A | F74: PPJ 3 vs 3 Atlantis FC | G74: PPJ | H74: 3 | I74: 3 | J74: Atlantis FC | K74: 3 | L74: 3 | S74: 2026-06-11|PPJ|Atlantis FC | T74: 1 | W74: 1 | X74: 1 | Y74: 1
A75: EST-00005 | B75: 46200 | C75: 0.45833333 | D75: FIN | E75: Kakkonen A | F75: MyPa 1 vs 2 Atlantis FC | G75: MyPa | H75: 1 | I75: 2 | J75: Atlantis FC | K75: 2 | L75: 1 | S75: 2026-06-27|MyPa|Atlantis FC | T75: 1 | W75: 1 | X75: 1 | Y75: 1
A76: EST-00006 | B76: 46207 | C76: 0.41666667 | D76: FIN | E76: Kakkonen A | F76: Atlantis FC 5 vs 1 PEPO | G76: Atlantis FC | H76: 5 | I76: 1 | J76: PEPO | K76: 1 | L76: 5 | S76: 2026-07-04|Atlantis FC|PEPO | T76: 1 | W76: 1 | X76: 1 | Y76: 1
A77: EST-00007 | B77: 46213 | C77: 0.52083333 | D77: FIN | E77: Kakkonen A | F77: Atlantis FC 3 vs 5 Kiffen | G77: Atlantis FC | H77: 3 | I77: 5 | J77: Kiffen | K77: 5 | L77: 3 | S77: 2026-07-10|Atlantis FC|Kiffen | T77: 1 | W77: 1 | X77: 1 | Y77: 1
A78: EST-00008 | B78: 46221 | C78: 0.375 | D78: FIN | E78: Kakkonen A | F78: Union Plaani 3 vs 6 Atlantis FC | G78: Union Plaani | H78: 3 | I78: 6 | J78: Atlantis FC | K78: 6 | L78: 3 | S78: 2026-07-18|Union Plaani|Atlantis FC | T78: 1 | W78: 1 | X78: 1 | Y78: 1
A79: EST-00009 | B79: 46228 | C79: 0.41666667 | D79: FIN | E79: Kakkonen A | F79: Atlantis FC 5 vs 3 HPS | G79: Atlantis FC | H79: 5 | I79: 3 | J79: HPS | K79: 3 | L79: 5 | S79: 2026-07-25|Atlantis FC|HPS | T79: 1 | W79: 1 | X79: 1 | Y79: 1
A80: EST-00011 | B80: 46171 | C80: 0.52083333 | D80: FIN | E80: Ykkösliiga | F80: KTP 1 vs 0 SJK Akatemia | G80: KTP | H80: 1 | I80: 0 | J80: SJK Akatemia | K80: 0 | L80: 1 | S80: 2026-05-29|KTP|SJK Akatemia | T80: 1 | W80: 1 | X80: 1 | Y80: 1
A81: EST-00012 | B81: 46182 | C81: 0.52083333 | D81: FIN | E81: Ykkösliiga | F81: SJK Akatemia 0 vs 0 Jippo | G81: SJK Akatemia | H81: 0 | I81: 0 | J81: Jippo | K81: 0 | L81: 0 | S81: 2026-06-09|SJK Akatemia|Jippo | T81: 1 | W81: 1 | X81: 1 | Y81: 1
A82: EST-00013 | B82: 46188 | C82: 0.52083333 | D82: FIN | E82: Ykkösliiga | F82: SJK Akatemia 0 vs 2 Haka | G82: SJK Akatemia | H82: 0 | I82: 2 | J82: Haka | K82: 2 | L82: 0 | S82: 2026-06-15|SJK Akatemia|Haka | T82: 1 | W82: 1 | X82: 1 | Y82: 1
... A276: EST-00241 | B276: 46229 | C276: 0.52083333 | D276: FIN | E276: Ykkönen | F276: KuPS Akatemia 2 vs 2 VJS | G276: KuPS Akatemia | H276: 2 | I276: 2 | J276: VJS | K276: 2 | L276: 2 | S276: 2026-07-26|KuPS Akatemia|VJS | T276: 1 | W276: 1 | X276: 1 | Y276: 1
A277: 00100-FIN | B277: 46241 | C277: 0.52083333 | D277: FIN | E277: Ykkönen | F277: KuPS Akatemia 0 vs 1 Inter Turku 2 | G277: KuPS Akatemia | H277: 0 | I277: 1 | J277: Inter Turku 2 | K277: 1 | L277: 0 | M277: Gols +/- | N277: Mais de 2.5 | O277: 1.225 | P277: 0.5 | Q277: Red | R277: -0.5 | S277: 2026-08-07|KuPS Akatemia|Inter Turku 2 | T277: 1 | W277: 1 | X277: 1 | Y277: 1
A278: 00101-FIN | B278: 46241 | C278: 0.52083333 | D278: FIN | E278: Kakkonen C | F278: Jaro 2 1 vs 3 JBK | G278: Jaro 2 | H278: 1 | I278: 3 | J278: JBK | K278: 3 | L278: 1 | M278: Gols +/- | N278: Mais de 2.0, 2.5 | O278: 1.2 | P278: 0.5 | Q278: Green | R278: 0.1 | S278: 2026-08-07|Jaro 2|JBK | T278: 1 | W278: 1 | X278: 1 | Y278: 1
A279: 00102-CHN | B279: 46241 | C279: 0.35763889 | D279: CHN | E279: Super League | F279: Beijing Guoan 4 vs 0 Shenzhen Xinpengcheng | G279: Beijing Guoan | H279: 4 | I279: 0 | J279: Shenzhen Xinpengcheng | K279: 0 | L279: 4 | M279: Gols +/- | N279: Mais de 2.0 | O279: 1.14 | P279: 0.5 | Q279: Green | R279: 0.07 | S279: 2026-08-07|Beijing Guoan|Shenzhen Xinpengcheng | T279: 1 | W279: 1 | X279: 1 | Y279: 1
A280: 00103-AUS | B280: 46241 | C280: 0.22916667 | D280: AUS | E280: NPL Queensland | F280: Lions FC 4 vs 2 Brisbane Roar NPL | G280: Lions FC | H280: 4 | I280: 2 | J280: Brisbane Roar NPL | K280: 2 | L280: 4 | M280: Gols +/- | N280: Mais de 2.5 | O280: 1.26 | P280: 0.5 | Q280: Green | R280: 0.13 | S280: 2026-08-07|Lions FC|Brisbane Roar NPL | T280: 1 | W280: 1 | X280: 1 | Y280: 1
A281: 00104-BOL | B281: 46239 | C281: 0.875 | D281: BOL | E281: Div. Profesional | F281: Bolívar 2 vs 1 Oriente Petrolero | G281: Bolívar | H281: 2 | I281: 1 | J281: Oriente Petrolero | K281: 1 | L281: 2 | M281: Gols +/- | N281: Mais de 2.0, 2.5 | O281: 1.17 | P281: 0.5 | Q281: Green | R281: 0.08 | S281: 2026-08-05|Bolívar|Oriente Petrolero | T281: 1 | W281: 1 | X281: 1 | Y281: 1
A282: 00105-BOL | B282: 46239 | C282: 0.79166667 | D282: BOL | E282: Div. Profesional | F282: Nacional Potosí 2 vs 3 The Strongest | G282: Nacional Potosí | H282: 2 | I282: 3 | J282: The Strongest | K282: 3 | L282: 2 | M282: Gols +/- | N282: Mais de 2.0 | O282: 1.225 | P282: 0.5 | Q282: Green | R282: 0.11 | S282: 2026-08-05|Nacional Potosí|The Strongest | T282: 1 | W282: 1 | X282: 1 | Y282: 1
A283: 00106-ISL | B283: 46239 | C283: 0.625 | D283: ISL | E283: Besta-deild karla (PL) | F283: Keflavík 3 vs 0 KA Akureyri | G283: Keflavík | H283: 3 | I283: 0 | J283: KA Akureyri | K283: 0 | L283: 3 | M283: Gols +/- | N283: Mais de 2.0, 2.5 | O283: 1.24 | P283: 0.5 | Q283: Green | R283: 0.12 | S283: 2026-08-05|Keflavík|KA Akureyri | T283: 1 | W283: 1 | X283: 1 | Y283: 1
A284: 00107-FIN | B284: 46239 | C284: 0.54166667 | D284: FIN | E284: Ykkönen | F284: VJS 0 vs 0 Keski-Uusimaa | G284: VJS | H284: 0 | I284: 0 | J284: Keski-Uusimaa | K284: 0 | L284: 0 | M284: Gols +/- | N284: Mais de 2.0 | O284: 1.125 | P284: 0.5 | Q284: Red | R284: -0.5 | S284: 2026-08-05|VJS|Keski-Uusimaa | T284: 1 | W284: 1 | X284: 1 | Y284: 1
A285: 00108-FIN | B285: 46239 | C285: 0.52083333 | D285: FIN | E285: Ykkönen | F285: SalPa 2 vs 1 JJK Jyvaskyla | G285: SalPa | H285: 2 | I285: 1 | J285: JJK Jyvaskyla | K285: 1 | L285: 2 | M285: Gols +/- | N285: Mais de 2.0 | O285: 1.13 | P285: 0.5 | Q285: Green | R285: 0.06 | S285: 2026-08-05|SalPa|JJK Jyvaskyla | T285: 1 | W285: 1 | X285: 1 | Y285: 1
A286: 00109-FIN | B286: 46239 | C286: 0.52083333 | D286: FIN | E286: Ykkönen | F286: RoPS (Rovaniemi) 2 vs 2 Jazz Pori | G286: RoPS (Rovaniemi) | H286: 2 | I286: 2 | J286: Jazz Pori | K286: 2 | L286: 2 | M286: Gols +/- | N286: Mais de 2.0, 2.5 | O286: 1.225 | P286: 0.5 | Q286: Green | R286: 0.11 | S286: 2026-08-05|RoPS (Rovaniemi)|Jazz Pori | T286: 1 | W286: 1 | X286: 1 | Y286: 1
A287: 00110-FIN | B287: 46239 | C287: 0.5 | D287: FIN | E287: Ykkönen | F287: OLS Oulu 4 vs 2 TPV | G287: OLS Oulu | H287: 4 | I287: 2 | J287: TPV | K287: 2 | L287: 4 | M287: Gols +/- | N287: Mais de 1.5, 2.0 | O287: 1.12 | P287: 0.5 | Q287: Green | R287: 0.06 | S287: 2026-08-05|OLS Oulu|TPV | T287: 1 | W287: 1 | X287: 1 | Y287: 1
A288: 00111-BOL | B288: 46238 | C288: 0.875 | D288: BOL | E288: Div. Profesional | F288: Guabirá 3 vs 0 Real Tomayapo | G288: Guabirá | H288: 3 | I288: 0 | J288: Real Tomayapo | K288: 0 | L288: 3 | M288: Gols +/- | N288: Mais de 1.5 | O288: 1.115 | P288: 0.5 | Q288: Green | R288: 0.06 | S288: 2026-08-04|Guabirá|Real Tomayapo | T288: 1 | W288: 1 | X288: 1 | Y288: 1
... A305: 00130-SWE | B305: 46237 | C305: 0.58333333 | D305: SWE | E305: Allsvenskan | F305: Halmstads BK 0 vs 2 IK Sirius | G305: Halmstads BK | H305: 0 | I305: 2 | J305: IK Sirius | K305: 2 | L305: 0 | M305: Gols +/- | N305: Mais de 1.5 | O305: 1.13 | P305: 0.5 | Q305: Green | R305: 0.07 | S305: 2026-08-03|Halmstads BK|IK Sirius | T305: 1 | W305: 1 | X305: 1 | Y305: 1
...

Sheet Ligas
A1: Liga | B1: Nível no País | C1: Partidas Únicas | D1: Média de Gols por Partida (Input) | E1: Média Efetiva da Liga | F1: Perfil da Liga | H1: País (aux) | I1: Liga (aux)
A2: ARG - Liga Profesional | B2: 1ª divisão | C2: =IF(A2="","",COUNTIFS(tblDados[País],H2,tblDados[Liga],I2,tblDados[Janela_12_Liga],1)) -> 4 | D2: 2.05 | E2: =IF(A2="","",IF(AND(I2<>"MLS-Cross",C2<30),"Insuficiente",IF(C2=0,"Insuficiente",(SUMIFS(tblDados[GM_M],tblDados[País],H2,tblDados[Liga],I2,tblDados[Janela_12_Liga],1)+SUMIFS(tblDados[GS_M],tblDados[País],H2,tblDados[Liga],I2,tblDados[Janela_12_Liga],1))/C2))) -> Insuficiente | F2: Poucos Gols | H2: =IF(A2="","",LEFT(A2,3)) -> ARG | I2: =IF(A2="","",_xlfn.TEXTAFTER(A2," - ")) -> Liga Profesional
A3: ARG - Primera Nacional | B3: 2ª divisão | C3: =IF(A3="","",COUNTIFS(tblDados[País],H3,tblDados[Liga],I3,tblDados[Janela_12_Liga],1)) -> 2 | D3: 1.92 | E3: =IF(A3="","",IF(AND(I3<>"MLS-Cross",C3<30),"Insuficiente",IF(C3=0,"Insuficiente",(SUMIFS(tblDados[GM_M],tblDados[País],H3,tblDados[Liga],I3,tblDados[Janela_12_Liga],1)+SUMIFS(tblDados[GS_M],tblDados[País],H3,tblDados[Liga],I3,tblDados[Janela_12_Liga],1))/C3))) -> Insuficiente | F3: Poucos Gols | H3: =IF(A3="","",LEFT(A3,3)) -> ARG | I3: =IF(A3="","",_xlfn.TEXTAFTER(A3," - ")) -> Primera Nacional
A4: BOL - Div. Profesional | B4: 3ª divisão | C4: =IF(A4="","",COUNTIFS(tblDados[País],H4,tblDados[Liga],I4,tblDados[Janela_12_Liga],1)) -> 97 | D4: 3.62 | E4: =IF(A4="","",IF(AND(I4<>"MLS-Cross",C4<30),"Insuficiente",IF(C4=0,"Insuficiente",(SUMIFS(tblDados[GM_M],tblDados[País],H4,tblDados[Liga],I4,tblDados[Janela_12_Liga],1)+SUMIFS(tblDados[GS_M],tblDados[País],H4,tblDados[Liga],I4,tblDados[Janela_12_Liga],1))/C4))) -> 2.9793814 | F4: Muitos Gols | H4: =IF(A4="","",LEFT(A4,3)) -> BOL | I4: =IF(A4="","",_xlfn.TEXTAFTER(A4," - ")) -> Div. Profesional
A5: BRA - Série A | B5: 3ª divisão | C5: =IF(A5="","",COUNTIFS(tblDados[País],H5,tblDados[Liga],I5,tblDados[Janela_12_Liga],1)) -> 124 | D5: 2.59 | E5: =IF(A5="","",IF(AND(I5<>"MLS-Cross",C5<30),"Insuficiente",IF(C5=0,"Insuficiente",(SUMIFS(tblDados[GM_M],tblDados[País],H5,tblDados[Liga],I5,tblDados[Janela_12_Liga],1)+SUMIFS(tblDados[GS_M],tblDados[País],H5,tblDados[Liga],I5,tblDados[Janela_12_Liga],1))/C5))) -> 2.5241935 | F5: Equilibrada | H5: =IF(A5="","",LEFT(A5,3)) -> BRA | I5: =IF(A5="","",_xlfn.TEXTAFTER(A5," - ")) -> Série A
A6: BRA - Série B | B6: 3ª divisão | C6: =IF(A6="","",COUNTIFS(tblDados[País],H6,tblDados[Liga],I6,tblDados[Janela_12_Liga],1)) -> 120 | D6: 2.31 | E6: =IF(A6="","",IF(AND(I6<>"MLS-Cross",C6<30),"Insuficiente",IF(C6=0,"Insuficiente",(SUMIFS(tblDados[GM_M],tblDados[País],H6,tblDados[Liga],I6,tblDados[Janela_12_Liga],1)+SUMIFS(tblDados[GS_M],tblDados[País],H6,tblDados[Liga],I6,tblDados[Janela_12_Liga],1))/C6))) -> 2.325 | F6: Poucos Gols | H6: =IF(A6="","",LEFT(A6,3)) -> BRA | I6: =IF(A6="","",_xlfn.TEXTAFTER(A6," - ")) -> Série B
A7: BRA - Série C | B7: 3ª divisão | C7: =IF(A7="","",COUNTIFS(tblDados[País],H7,tblDados[Liga],I7,tblDados[Janela_12_Liga],1)) -> 121 | D7: 2.09 | E7: =IF(A7="","",IF(AND(I7<>"MLS-Cross",C7<30),"Insuficiente",IF(C7=0,"Insuficiente",(SUMIFS(tblDados[GM_M],tblDados[País],H7,tblDados[Liga],I7,tblDados[Janela_12_Liga],1)+SUMIFS(tblDados[GS_M],tblDados[País],H7,tblDados[Liga],I7,tblDados[Janela_12_Liga],1))/C7))) -> 2.2727273 | F7: Poucos Gols | H7: =IF(A7="","",LEFT(A7,3)) -> BRA | I7: =IF(A7="","",_xlfn.TEXTAFTER(A7," - ")) -> Série C
A8: CAN - Premier League | B8: 3ª divisão | C8: =IF(A8="","",COUNTIFS(tblDados[País],H8,tblDados[Liga],I8,tblDados[Janela_12_Liga],1)) -> 49 | D8: 2.5 | E8: =IF(A8="","",IF(AND(I8<>"MLS-Cross",C8<30),"Insuficiente",IF(C8=0,"Insuficiente",(SUMIFS(tblDados[GM_M],tblDados[País],H8,tblDados[Liga],I8,tblDados[Janela_12_Liga],1)+SUMIFS(tblDados[GS_M],tblDados[País],H8,tblDados[Liga],I8,tblDados[Janela_12_Liga],1))/C8))) -> 3.0612245 | F8: Equilibrada | H8: =IF(A8="","",LEFT(A8,3)) -> CAN | I8: =IF(A8="","",_xlfn.TEXTAFTER(A8," - ")) -> Premier League
A9: CHI - Liga de Primera | B9: 3ª divisão | C9: =IF(A9="","",COUNTIFS(tblDados[País],H9,tblDados[Liga],I9,tblDados[Janela_12_Liga],1)) -> 98 | D9: 2.5 | E9: =IF(A9="","",IF(AND(I9<>"MLS-Cross",C9<30),"Insuficiente",IF(C9=0,"Insuficiente",(SUMIFS(tblDados[GM_M],tblDados[País],H9,tblDados[Liga],I9,tblDados[Janela_12_Liga],1)+SUMIFS(tblDados[GS_M],tblDados[País],H9,tblDados[Liga],I9,tblDados[Janela_12_Liga],1))/C9))) -> 3.0714286 | F9: Equilibrada | H9: =IF(A9="","",LEFT(A9,3)) -> CHI | I9: =IF(A9="","",_xlfn.TEXTAFTER(A9," - ")) -> Liga de Primera
A10: ECU - LigaPro Serie A | B10: 1ª divisão | C10: =IF(A10="","",COUNTIFS(tblDados[País],H10,tblDados[Liga],I10,tblDados[Janela_12_Liga],1)) -> 96 | D10: 2.5 | E10: =IF(A10="","",IF(AND(I10<>"MLS-Cross",C10<30),"Insuficiente",IF(C10=0,"Insuficiente",(SUMIFS(tblDados[GM_M],tblDados[País],H10,tblDados[Liga],I10,tblDados[Janela_12_Liga],1)+SUMIFS(tblDados[GS_M],tblDados[País],H10,tblDados[Liga],I10,tblDados[Janela_12_Liga],1))/C10))) -> 2.3541667 | F10: Equilibrada | H10: =IF(A10="","",LEFT(A10,3)) -> ECU | I10: =IF(A10="","",_xlfn.TEXTAFTER(A10," - ")) -> LigaPro Serie A
A11: FIN - Veikkausliiga | B11: 2ª divisão | C11: =IF(A11="","",COUNTIFS(tblDados[País],H11,tblDados[Liga],I11,tblDados[Janela_12_Liga],1)) -> 75 | D11: 2.6 | E11: =IF(A11="","",IF(AND(I11<>"MLS-Cross",C11<30),"Insuficiente",IF(C11=0,"Insuficiente",(SUMIFS(tblDados[GM_M],tblDados[País],H11,tblDados[Liga],I11,tblDados[Janela_12_Liga],1)+SUMIFS(tblDados[GS_M],tblDados[País],H11,tblDados[Liga],I11,tblDados[Janela_12_Liga],1))/C11))) -> 2.72 | F11: Equilibrada | H11: =IF(A11="","",LEFT(A11,3)) -> FIN | I11: =IF(A11="","",_xlfn.TEXTAFTER(A11," - ")) -> Veikkausliiga
A12: FIN - Ykkösliiga | B12: 1ª divisão | C12: =IF(A12="","",COUNTIFS(tblDados[País],H12,tblDados[Liga],I12,tblDados[Janela_12_Liga],1)) -> 62 | D12: 2.51 | E12: =IF(A12="","",IF(AND(I12<>"MLS-Cross",C12<30),"Insuficiente",IF(C12=0,"Insuficiente",(SUMIFS(tblDados[GM_M],tblDados[País],H12,tblDados[Liga],I12,tblDados[Janela_12_Liga],1)+SUMIFS(tblDados[GS_M],tblDados[País],H12,tblDados[Liga],I12,tblDados[Janela_12_Liga],1))/C12))) -> 2.483871 | F12: Equilibrada | H12: =IF(A12="","",LEFT(A12,3)) -> FIN | I12: =IF(A12="","",_xlfn.TEXTAFTER(A12," - ")) -> Ykkösliiga
A13: FIN - Ykkönen | B13: 1ª divisão | C13: =IF(A13="","",COUNTIFS(tblDados[País],H13,tblDados[Liga],I13,tblDados[Janela_12_Liga],1)) -> 73 | D13: 3.57 | E13: =IF(A13="","",IF(AND(I13<>"MLS-Cross",C13<30),"Insuficiente",IF(C13=0,"Insuficiente",(SUMIFS(tblDados[GM_M],tblDados[País],H13,tblDados[Liga],I13,tblDados[Janela_12_Liga],1)+SUMIFS(tblDados[GS_M],tblDados[País],H13,tblDados[Liga],I13,tblDados[Janela_12_Liga],1))/C13))) -> 3.5068493 | F13: Muitos Gols | H13: =IF(A13="","",LEFT(A13,3)) -> FIN | I13: =IF(A13="","",_xlfn.TEXTAFTER(A13," - ")) -> Ykkönen
... A41: KOR - K League 2 | B41: 2ª divisão | C41: =IF(A41="","",COUNTIFS(tblDados[País],H41,tblDados[Liga],I41,tblDados[Janela_12_Liga],1)) -> 78 | D41: 2.7 | E41: =IF(A41="","",IF(AND(I41<>"MLS-Cross",C41<30),"Insuficiente",IF(C41=0,"Insuficiente",(SUMIFS(tblDados[GM_M],tblDados[País],H41,tblDados[Liga],I41,tblDados[Janela_12_Liga],1)+SUMIFS(tblDados[GS_M],tblDados[País],H41,tblDados[Liga],I41,tblDados[Janela_12_Liga],1))/C41))) -> 2.6025641 | F41: Equilibrada | H41: =IF(A41="","",LEFT(A41,3)) -> KOR | I41: =IF(A41="","",_xlfn.TEXTAFTER(A41," - ")) -> K League 2

Sheet Equipes
A1: Equipe | B1: País - Liga | C1: IPM | D1: IPV | E1: TJM | F1: TJV | G1: TJT | H1: Média de Gols Marcados | I1: Média Golds da Liga | J1: % Sem Marcar | K1: % Over 0.5 | L1: % Over 1.5 | M1: % Over 2.5 | N1: % Over 3.5 | O1: % BTTS | P1: Variância | Q1: Dispersão | R1: Modelo Estatístico | S1: GMC | T1: GMV | U1: TGM | V1: MGM | W1: GSC | X1: GSV | Y1: TGS | Z1: MGS | AA1: FAM | AB1: VDM | AC1: FAV | AD1: VDV
A2: Aalesunds FK | B2: NOR - Eliteserien | C2: 3.8333333 | D2: 3.3333333 | E2: 6 | F2: 6 | G2: 12 | H2: 1.3333333 | I2: 2.5 | J2: 0.16666667 | K2: 1 | L2: 0.91666667 | M2: 0.58333333 | N2: 0.41666667 | O2: 0.83333333 | P2: 0.72222222 | Q2: 0.84983659 | R2: Poisson | S2: 10 | T2: 6 | U2: 16 | V2: 1.3333333 | W2: 13 | X2: 14 | Y2: 27 | Z2: 2.25 | AA2: 1.6666667 | AB2: 2.1666667 | AC2: 1 | AD2: 2.3333333
A3: ABB | B3: BOL - Div. Profesional | C3: 3.8333333 | D3: 4.1666667 | E3: 6 | F3: 6 | G3: 12 | H3: 1.8333333 | I3: 3.62 | J3: 0.083333333 | K3: 1 | L3: 0.91666667 | M3: 0.83333333 | N3: 0.75 | O3: 0.91666667 | P3: 1.3055556 | Q3: 1.1426091 | R3: Poisson | S3: 14 | T3: 8 | U3: 22 | V3: 1.8333333 | W3: 9 | X3: 17 | Y3: 26 | Z3: 2.1666667 | AA3: 2.3333333 | AB3: 1.5 | AC3: 1.3333333 | AD3: 2.8333333
A4: AC Oulu | B4: FIN - Veikkausliiga | C4: 1.8571429 | D4: 2.4 | E4: 7 | F4: 5 | G4: 12 | H4: 0.83333333 | I4: 2.6 | J4: 0.33333333 | K4: 0.91666667 | L4: 0.58333333 | M4: 0.33333333 | N4: 0.083333333 | O4: 0.41666667 | P4: 0.47222222 | Q4: 0.68718427 | R4: Poisson | S4: 7 | T4: 3 | U4: 10 | V4: 0.83333333 | W4: 6 | X4: 9 | Y4: 15 | Z4: 1.25 | AA4: 1 | AB4: 0.85714286 | AC4: 0.6 | AD4: 1.8
A5: Adelaide City | B5: AUS - NPL South Australia | C5: 2.8571429 | D5: 1.6 | E5: 7 | F5: 5 | G5: 12 | H5: 1.8333333 | I5: 3.7 | J5: 0.16666667 | K5: 0.83333333 | L5: 0.58333333 | M5: 0.5 | N5: 0.33333333 | O5: 0.33333333 | P5: 1.6388889 | Q5: 1.280191 | R5: Poisson | S5: 15 | T5: 7 | U5: 22 | V5: 1.8333333 | W5: 5 | X5: 1 | Y5: 6 | Z5: 0.5 | AA5: 2.1428571 | AB5: 0.71428571 | AC5: 1.4 | AD5: 0.2
A6: Adelaide Comets | B6: AUS - NPL South Australia | C6: 2.8333333 | D6: 2 | E6: 6 | F6: 6 | G6: 12 | H6: 1.0833333 | I6: 3.7 | J6: 0.41666667 | K6: 0.83333333 | L6: 0.5 | M6: 0.41666667 | N6: 0.41666667 | O6: 0.41666667 | P6: 1.5763889 | Q6: 1.2555433 | R6: Poisson | S6: 9 | T6: 4 | U6: 13 | V6: 1.0833333 | W6: 8 | X6: 8 | Y6: 16 | Z6: 1.3333333 | AA6: 1.5 | AB6: 1.3333333 | AC6: 0.66666667 | AD6: 1.3333333
A7: Adelaide United U23 | B7: AUS - NPL South Australia | C7: 2.4285714 | D7: 2.6 | E7: 7 | F7: 5 | G7: 12 | H7: 1.4166667 | I7: 3.7 | J7: 0.33333333 | K7: 0.75 | L7: 0.75 | M7: 0.41666667 | N7: 0.25 | O7: 0.41666667 | P7: 2.0763889 | Q7: 1.440968 | R7: Poisson | S7: 11 | T7: 6 | U7: 17 | V7: 1.4166667 | W7: 6 | X7: 7 | Y7: 13 | Z7: 1.0833333 | AA7: 1.5714286 | AB7: 0.85714286 | AC7: 1.2 | AD7: 1.4
A8: Aegir | B8: ISL - Lengjudeildin (1ªD) | C8: 3.8333333 | D8: 5.1666667 | E8: 6 | F8: 6 | G8: 12 | H8: 1.25 | I8: 3.55 | J8: 0.33333333 | K8: 0.91666667 | L8: 0.83333333 | M8: 0.75 | N8: 0.66666667 | O8: 0.66666667 | P8: 1.1875 | Q8: 1.0897247 | R8: Poisson | S8: 6 | T8: 9 | U8: 15 | V8: 1.25 | W8: 17 | X8: 22 | Y8: 39 | Z8: 3.25 | AA8: 1 | AB8: 2.8333333 | AC8: 1.5 | AD8: 3.6666667
A9: AFC Eskilstuna | B9: SWE - 1ª D Norra | C9: 2 | D9: 3.5 | E9: 6 | F9: 6 | G9: 12 | H9: 1.5833333 | I9: 2.5 | J9: 0.25 | K9: 0.91666667 | L9: 0.75 | M9: 0.58333333 | N9: 0.33333333 | O9: 0.5 | P9: 1.5763889 | Q9: 1.2555433 | R9: Poisson | S9: 5 | T9: 14 | U9: 19 | V9: 1.5833333 | W9: 7 | X9: 7 | Y9: 14 | Z9: 1.1666667 | AA9: 0.83333333 | AB9: 1.1666667 | AC9: 2.3333333 | AD9: 1.1666667
A10: AFC Malmö (Ariana FC Malmö) | B10: SWE - 1ª D Södra | C10: 3.1428571 | D10: 3.6 | E10: 7 | F10: 5 | G10: 12 | H10: 2.25 | I10: 2.5 | J10: 0.083333333 | K10: 1 | L10: 0.83333333 | M10: 0.75 | N10: 0.41666667 | O10: 0.58333333 | P10: 1.6875 | Q10: 1.2990381 | R10: Poisson | S10: 12 | T10: 15 | U10: 27 | V10: 2.25 | W10: 10 | X10: 3 | Y10: 13 | Z10: 1.0833333 | AA10: 1.7142857 | AB10: 1.4285714 | AC10: 3 | AD10: 0.6
A11: Afturelding | B11: ISL - Lengjudeildin (1ªD) | C11: 5.6666667 | D11: 3.6666667 | E11: 6 | F11: 6 | G11: 12 | H11: 3.1666667 | I11: 3.55 | J11: 0.083333333 | K11: 1 | L11: 0.91666667 | M11: 0.75 | N11: 0.66666667 | O11: 0.75 | P11: 5.1388889 | Q11: 2.2669118 | R11: Poisson | S11: 26 | T11: 12 | U11: 38 | V11: 3.1666667 | W11: 8 | X11: 10 | Y11: 18 | Z11: 1.5 | AA11: 4.3333333 | AB11: 1.3333333 | AC11: 2 | AD11: 1.6666667
A12: Ahlafors IF | B12: SWE - 2ª D Norra Götaland | C12: 3.4 | D12: 3.1428571 | E12: 5 | F12: 7 | G12: 12 | H12: 2.1666667 | I12: 2.5 | J12: 0.083333333 | K12: 0.91666667 | L12: 0.91666667 | M12: 0.58333333 | N12: 0.5 | O12: 0.58333333 | P12: 1.9722222 | Q12: 1.4043583 | R12: Poisson | S12: 11 | T12: 15 | U12: 26 | V12: 2.1666667 | W12: 6 | X12: 7 | Y12: 13 | Z12: 1.0833333 | AA12: 2.2 | AB12: 1.2 | AC12: 2.1428571 | AD12: 1
A13: AIFK | B13: FIN - Kakkonen B | C13: 2.6666667 | D13: 3.1666667 | E13: 6 | F13: 6 | G13: 12 | H13: 2 | I13: 3.56 | J13: 0.16666667 | K13: 1 | L13: 0.75 | M13: 0.5 | N13: 0.25 | O13: 0.66666667 | P13: 2.6666667 | Q13: 1.6329932 | R13: Poisson | S13: 10 | T13: 14 | U13: 24 | V13: 2 | W13: 6 | X13: 5 | Y13: 11 | Z13: 0.91666667 | AA13: 1.6666667 | AB13: 1 | AC13: 2.3333333 | AD13: 0.83333333
... A471: Zhejiang Professional FC | B471: CHN - Super League | C471: 4.4 | D471: 3.2857143 | E471: 5 | F471: 7 | G471: 12 | H471: 1.8333333 | I471: 2.5 | J471: 0.083333333 | K471: 1 | L471: 1 | M471: 0.75 | N471: 0.58333333 | O471: 0.83333333 | P471: 1.1388889 | Q471: 1.0671874 | R471: Poisson | S471: 11 | T471: 11 | U471: 22 | V471: 1.8333333 | W471: 11 | X471: 12 | Y471: 23 | Z471: 1.9166667 | AA471: 2.2 | AB471: 2.2 | AC471: 1.5714286 | AD471: 1.7142857
A472: Argentinos Jrs | B472: ARG - Primera Nacional | C472: 3 | E472: 1 | F472: 0 | G472: 1 | H472: 3 | I472: 1.92 | J472: 0 | K472: 1 | L472: 1 | M472: 1 | N472: 0 | O472: 0 | P472: 0 | Q472: 0 | R472: Amostra Insuficiente | S472: 3 | T472: 0 | U472: 3 | V472: 3 | W472: 0 | X472: 0 | Y472: 0 | Z472: 0 | AA472: 3 | AB472: 0
A473: Chivas Guadalajara | B473: MEX - Liga MX | D473: 2 | E473: 0 | F473: 1 | G473: 1 | H473: 1 | I473: 3.91 | J473: 0 | K473: 1 | L473: 1 | M473: 0 | N473: 0 | O473: 1 | P473: 0 | Q473: 0 | R473: Amostra Insuficiente | S473: 0 | T473: 1 | U473: 1 | V473: 1 | W473: 0 | X473: 1 | Y473: 1 | Z473: 1 | AC473: 1 | AD473: 1
A474: Club León | B474: MEX - Liga MX | C474: 1 | E474: 1 | F474: 0 | G474: 1 | H474: 1 | I474: 3.91 | J474: 0 | K474: 1 | L474: 0 | M474: 0 | N474: 0 | O474: 0 | P474: 0 | Q474: 0 | R474: Amostra Insuficiente | S474: 1 | T474: 0 | U474: 1 | V474: 1 | W474: 0 | X474: 0 | Y474: 0 | Z474: 0 | AA474: 1 | AB474: 0
A475: Defensa y Justicia | B475: ARG - Liga Profesional | C475: 3 | E475: 1 | F475: 0 | G475: 1 | H475: 2 | I475: 2.05 | J475: 0 | K475: 1 | L475: 1 | M475: 1 | N475: 0 | O475: 1 | P475: 0 | Q475: 0 | R475: Amostra Insuficiente | S475: 2 | T475: 0 | U475: 2 | V475: 2 | W475: 1 | X475: 0 | Y475: 1 | Z475: 1 | AA475: 2 | AB475: 1
A476: Deportivo Riestra | B476: ARG - Liga Profesional | D476: 3 | E476: 0 | F476: 1 | G476: 1 | H476: 1 | I476: 2.05 | J476: 0 | K476: 1 | L476: 1 | M476: 1 | N476: 0 | O476: 1 | P476: 0 | Q476: 0 | R476: Amostra Insuficiente | S476: 0 | T476: 1 | U476: 1 | V476: 1 | W476: 0 | X476: 2 | Y476: 2 | Z476: 2 | AC476: 1 | AD476: 2
A477: Estudiantes Rio Cuarto | B477: ARG - Primera Nacional | D477: 3 | E477: 0 | F477: 1 | G477: 1 | H477: 0 | I477: 1.92 | J477: 1 | K477: 1 | L477: 1 | M477: 1 | N477: 0 | O477: 0 | P477: 0 | Q477: 0 | R477: Amostra Insuficiente | S477: 0 | T477: 0 | U477: 0 | V477: 0 | W477: 0 | X477: 3 | Y477: 3 | Z477: 3 | AC477: 0 | AD477: 3
A478: Gimnasia LP | B478: ARG - Liga Profesional | C478: 1 | E478: 1 | F478: 0 | G478: 1 | H478: 1 | I478: 2.05 | J478: 0 | K478: 1 | L478: 0 | M478: 0 | N478: 0 | O478: 0 | P478: 0 | Q478: 0 | R478: Amostra Insuficiente | S478: 1 | T478: 0 | U478: 1 | V478: 1 | W478: 0 | X478: 0 | Y478: 0 | Z478: 0 | AA478: 1 | AB478: 0
A479: Huracán | B479: ARG - Liga Profesional | D479: 3 | E479: 0 | F479: 1 | G479: 1 | H479: 1 | I479: 2.05 | J479: 0 | K479: 1 | L479: 1 | M479: 1 | N479: 0 | O479: 1 | P479: 0 | Q479: 0 | R479: Amostra Insuficiente | S479: 0 | T479: 1 | U479: 1 | V479: 1 | W479: 0 | X479: 2 | Y479: 2 | Z479: 2 | AC479: 1 | AD479: 2
A480: Independiente Rivadavia | B480: ARG - Liga Profesional | C480: 3 | E480: 1 | F480: 0 | G480: 1 | H480: 2 | I480: 2.05 | J480: 0 | K480: 1 | L480: 1 | M480: 1 | N480: 0 | O480: 1 | P480: 0 | Q480: 0 | R480: Amostra Insuficiente | S480: 2 | T480: 0 | U480: 2 | V480: 2 | W480: 1 | X480: 0 | Y480: 1 | Z480: 1 | AA480: 2 | AB480: 1
A481: Instituto Córdoba | B481: ARG - Liga Profesional | C481: 3 | E481: 1 | F481: 0 | G481: 1 | H481: 2 | I481: 2.05 | J481: 0 | K481: 1 | L481: 1 | M481: 1 | N481: 0 | O481: 1 | P481: 0 | Q481: 0 | R481: Amostra Insuficiente | S481: 2 | T481: 0 | U481: 2 | V481: 2 | W481: 1 | X481: 0 | Y481: 1 | Z481: 1 | AA481: 2 | AB481: 1
A482: M. Wanderers | B482: URU - Liga AUF | D482: 2 | E482: 0 | F482: 1 | G482: 1 | H482: 2 | I482: 2.5 | J482: 0 | K482: 1 | L482: 1 | M482: 0 | N482: 0 | O482: 0 | P482: 0 | Q482: 0 | R482: Amostra Insuficiente | S482: 0 | T482: 2 | U482: 2 | V482: 2 | W482: 0 | X482: 0 | Y482: 0 | Z482: 0 | AC482: 2 | AD482: 0
A483: Montevideo City Torque | B483: URU - Liga AUF | C483: 2 | E483: 1 | F483: 0 | G483: 1 | H483: 0 | I483: 2.5 | J483: 1 | K483: 1 | L483: 1 | M483: 0 | N483: 0 | O483: 0 | P483: 0 | Q483: 0 | R483: Amostra Insuficiente | S483: 0 | T483: 0 | U483: 0 | V483: 0 | W483: 2 | X483: 0 | Y483: 2 | Z483: 2 | AA483: 0 | AB483: 2
A484: Pachuca | B484: MEX - Liga MX | D484: 1 | E484: 0 | F484: 1 | G484: 1 | H484: 0 | I484: 3.91 | J484: 1 | K484: 1 | L484: 0 | M484: 0 | N484: 0 | O484: 0 | P484: 0 | Q484: 0 | R484: Amostra Insuficiente | S484: 0 | T484: 0 | U484: 0 | V484: 0 | W484: 0 | X484: 1 | Y484: 1 | Z484: 1 | AC484: 0 | AD484: 1
